Workbook

Sheet 00_Read_Me
A1: The Hermes Way
A2: The working database for what 'Hermes, fully realized' actually means — built 2026-10-03, meant to keep growing.
A4: WHAT THIS WORKBOOK IS
A5: A flat, execution-level inventory of every feature required to realize Hermes as a complete personal-agent
A6: platform — organized by capability domain (tabs 01-15), not by phase or timeline. Each row is one concrete,
A7: checkable thing. This is the working feature backlog, not the authoritative record — per this project's
A8: CLAUDE.md, the catalog (Postgres + PostgREST at 192.168.40.2:3003, tagged 'hermes') is the single source of
A9: truth for decisions and facts. Keep this workbook consistent with the catalog; when they disagree, the
A10: catalog wins and this file should be corrected.
A12: THE ONE RULE EVERYTHING IS CHECKED AGAINST
A13: Hermes = hermes-vps. The home network (w_workstation, WireGuard, the local LLM, Salt, MeshCentral) is a
A14: swappable CAPABILITY PROVIDER Hermes reaches over a tunnel — never a place Hermes itself runs, and never a
... A85: Found 2026-10-05: processed a 255-page community practitioner reference and hermesbible.com's bulk-downloadable llms-full.txt (D8_Advanced_Reference). Corrected TM-07 (Nous Tool Gateway is 4 Portal-gated tools, not '5 exec backends' -- that's actually the 7 terminal backends). Found a 4th self-improvement mechanism (GEPA, offline skill evolution via companion repo) and a real credential-protection stack (hermes egress / iron-proxy + Bitwarden, Docker-backend only, matches CR-17). Flagged a verification gap on CR-03 (systemd linger required for true reboot survival, not just logout) and closed the open blockers on IM-01 (SOUL.md template) and IA-05 (exact verified Telegram sequence). User decided: SSH access for execution (new CR-18, not yet provided), Home Assistant existence left open (new HN-09), voice interface explicitly deferred (IA-08).

Sheet 00_Hermes_Way_Standards
A1: The Hermes Way — Standards
A2: The principles every row in tabs 01-15 is checked against. Re-run this check whenever a new capability is added.
A4: # | B4: Standard | C4: What it means in practice | D4: Currently honored? | E4: Current gap, if any | F4: Owned by
A5: 1 | B5: Single source of truth for identity & state | C5: One memory, one identity, reachable identically from every interface — no split-brain between web UI / Desktop / future Telegram. | D5: No | E5: 02_Identity_Memory — session store not confirmed single, SOUL.md/MEMORY.md/USER.md not even committed yet | F5: Hermes Design Specialist
A6: 2 | B6: Core/capability separation | C6: Hermes's core (identity, routing, tools, web presence) lives only on hermes-vps. The home network is a capability provider, swappable without breaking the core. | D6: Partial | E6: 06_Home_Network_Boundary — Salt/MeshCentral added beyond the 2026-09-23 'local LLM only' decision | F6: Hermes Design Specialist
A7: 3 | B7: Graceful degradation, fail-safe default | C7: Losing any optional capability (local model, WireGuard link) degrades to a known-good fallback automatically — never an error, never silent wrong answers. | D7: Unverified | E7: 03_Model_Routing_Resilience MR-05 — the WireGuard-down fire drill has never actually been run | F7: Model/Routing Engineer
A8: 4 | B8: Least privilege | C8: Every credential and tool scoped to the minimum it needs. salt-hermes-infra (no wheel/runner) is the model to copy everywhere else. | D8: Partial | E8: 04_Tool_MCP_Layer TM-11, 12_Security_Hardening SH-04 — only Salt's scope has actually been reviewed this way | F8: Security Reviewer
A9: 5 | B9: One deployment per capability | C9: A given tool/capability exists in exactly one place. No copy-per-environment to keep in sync by hand. | D9: No | E9: vault_mcp.py is deployed 4x (hermes-vps, Claude Code, Codex, project .codex) — see TM-06 / SV-12 | F9: Hermes Design Specialist
A10: 6 | B10: Reproducible, not hand-built | C10: Infra/config changes are scripted and repeatable, not one-off manual edits nobody can redo identically. | D10: Partial | E10: 01_Core_Runtime CR-13 — a raw YAML parse+dump already silently destroyed config.yaml's comments once | F10: Platform/SRE
A11: 7 | B11: Secrets never in plaintext at rest outside the vault | C11: Every real credential lives only in the vault; config files and shares hold no plaintext secrets. | D11: No | E11: 05_Secrets_Vault SV-08 — /Dockers share exposes every container's .env in plaintext by design | F11: Secrets Custodian
A12: 8 | B12: Observable without SSH | C12: Every critical path (tunnel, local model, gateway, VPS) has a health signal a human can see without logging into a box. | D12: No | E12: 09_Observability — no alerting or dashboard exists for any of these yet | F12: Observability
A13: 9 | B13: Backups are tested, not just taken | C13: A backup that's never been restored is a hypothesis. | D13: No | E13: 10_Backup_DR BD-05 — no restore has ever been tested, and hermes-vps itself isn't backed up at all (BD-02) | F13: Platform/SRE
A14: 10 | B14: Repeatable promotion path for new capabilities | C14: Turning a home-network resource into a Hermes tool follows a documented playbook, not ad hoc judgment each time. | D14: No | E14: 04_Tool_MCP_Layer TM-10, 13_Governance GV-01 — no playbook written yet | F14: Hermes Design Specialist
A15: 11 | B15: Cost is visible and bounded | C15: Spend on every paid tier (Codex, Modal) is visible and capped, not discovered after the fact. | D15: Partial | E15: 11_Cost_Subscriptions CS-04/CS-05 — Vultr and Plus are known; Modal and a total rollup are not | F15: Product Owner (Mark)
A16: 12 | B16: Exposure is reviewed before it goes live, not after | C16: New network/tool exposure gets a security pass before shipping, not a retroactive audit. | D16: No | E16: 12_Security_Hardening SH-02 — the gateway's unauthenticated-shell combination shipped and is still live | F16: Security Reviewer
A17: 13 | B17: Changes are tracked | C17: Who changed hermes-vps's config, and when, is recorded somewhere durable. | D17: No | E17: 13_Governance_Change_Mgmt GV-03 — no change log exists | F17: Hermes Design Specialist

Sheet 00_Roles
A1: Roles
A2: One person (you) plays all of these today — naming them separately keeps 'who approves this' and 'who's affected by this' distinct.
A4: Role | B4: Charter | C4: Decides / owns | D4: Tabs where this role appears most
A5: Hermes Design Specialist | B5: Guards architectural coherence — the one role whose job is to keep asking 'does this belong on the VPS or the home network, and does it match the Hermes Way standards.' Reviews any new capability BEFORE it's built, not after. | C5: Where a capability lives; whether scope creep (like Salt/MeshCentral) gets ratified or rolled back; final call on anything tagged Violation. | D5: 00_Hermes_Way_Standards, 02_Identity_Memory, 06_Home_Network_Boundary, 13_Governance
A6: Platform / SRE | B6: Keeps hermes-vps itself alive, patched, backed up, and reproducible. | C6: VPS infra, Dokploy, systemd services, backup/restore, patch cadence. | D6: 01_Core_Runtime, 10_Backup_DR
A7: Secrets Custodian | B7: Owns the vault end to end — what's in it, what's still outside it, rotation. | C7: What gets vaulted, in what order, and the rotation policy. | D7: 05_Secrets_Vault
A8: Model / Routing Engineer | B8: Owns the local-vs-Codex decision logic and the local runtime itself. | C8: Runtime/model choice on w_workstation; routing/judge behavior; the WireGuard-down fire drill. | D8: 03_Model_Routing_Resilience, 07_Local_Inference
A9: Security Reviewer | B9: Finds and closes exposure — the role that would have flagged the gateway shell-access combo before it shipped. | C9: Network exposure, least-privilege scoping, incident response. | D9: 06_Home_Network_Boundary, 12_Security_Hardening
A10: Home-Network Liaison | B10: Represents the home network's interests as a capability provider — keeps it from quietly becoming a second place Hermes 'lives.' | C10: What crosses the WireGuard tunnel and why; Salt/MeshCentral scope. | D10: 06_Home_Network_Boundary, 07_Local_Inference, 04_Tool_MCP_Layer
A11: Interface Engineer | B11: Owns every door into Hermes — web UI, Desktop, Telegram — and that they all lead to the same place. | C11: Auth mechanism, channel rollout, cross-interface continuity testing. | D11: 08_Interfaces_Access
A12: Observability | B12: Makes sure state is visible without SSH. | C12: What gets logged, alerted, and dashboarded. | D12: 09_Observability
A13: Product Owner (Mark) | B13: Final authority — approves spend, approves the finish line, decides when Claude Pro actually gets canceled. | C13: Budget, go/no-go on CS-03, which open risks are acceptable to carry. | D13: 00_Scorecard, 11_Cost_Subscriptions

Sheet 00_Scorecard
A1: Scorecard — the point-based finish line
A2: Points reflect how load-bearing a row is, not effort. Earned points update automatically as Status changes on each tab.
A4: Tab | B4: Domain | C4: Total Points | D4: Points Earned | E4: % Complete
A5: 01_Core_Runtime | B5: Hermes Core Runtime | C5: =SUM('01_Core_Runtime'!G5:G51) | D5: =SUM('01_Core_Runtime'!H5:H51) | E5: =IFERROR(D5/C5,0)
A6: 02_Identity_Memory | B6: Identity & Memory Continuity | C6: =SUM('02_Identity_Memory'!G5:G43) | D6: =SUM('02_Identity_Memory'!H5:H43) | E6: =IFERROR(D6/C6,0)
A7: 03_Model_Routing_Resilience | B7: Model, Provider & Resilience | C7: =SUM('03_Model_Routing_Resilience'!G5:G47) | D7: =SUM('03_Model_Routing_Resilience'!H5:H47) | E7: =IFERROR(D7/C7,0)
A8: 04_Tool_MCP_Layer | B8: Tool / MCP Capability Layer | C8: =SUM('04_Tool_MCP_Layer'!G5:G48) | D8: =SUM('04_Tool_MCP_Layer'!H5:H48) | E8: =IFERROR(D8/C8,0)
A9: 05_Secrets_Vault | B9: Secrets & Vault | C9: =SUM('05_Secrets_Vault'!G5:G49) | D9: =SUM('05_Secrets_Vault'!H5:H49) | E9: =IFERROR(D9/C9,0)
A10: 06_Home_Network_Boundary | B10: Home-Network Capability Boundary | C10: =SUM('06_Home_Network_Boundary'!G5:G42) | D10: =SUM('06_Home_Network_Boundary'!H5:H42) | E10: =IFERROR(D10/C10,0)
A11: 07_Local_Inference | B11: Local Inference Tier | C11: =SUM('07_Local_Inference'!G5:G46) | D11: =SUM('07_Local_Inference'!H5:H46) | E11: =IFERROR(D11/C11,0)
A12: 08_Interfaces_Access | B12: Interfaces & Access Paths | C12: =SUM('08_Interfaces_Access'!G5:G44) | D12: =SUM('08_Interfaces_Access'!H5:H44) | E12: =IFERROR(D12/C12,0)
A13: 09_Observability | B13: Observability | C13: =SUM('09_Observability'!G5:G40) | D13: =SUM('09_Observability'!H5:H40) | E13: =IFERROR(D13/C13,0)
A14: 10_Backup_DR | B14: Backup & Disaster Recovery | C14: =SUM('10_Backup_DR'!G5:G40) | D14: =SUM('10_Backup_DR'!H5:H40) | E14: =IFERROR(D14/C14,0)
A15: 11_Cost_Subscriptions | B15: Cost & Subscriptions | C15: =SUM('11_Cost_Subscriptions'!G5:G40) | D15: =SUM('11_Cost_Subscriptions'!H5:H40) | E15: =IFERROR(D15/C15,0)
A16: 12_Security_Hardening | B16: Security & Hardening | C16: =SUM('12_Security_Hardening'!G5:G42) | D16: =SUM('12_Security_Hardening'!H5:H42) | E16: =IFERROR(D16/C16,0)
A17: 13_Governance_Change_Mgmt | B17: Governance & Change Management | C17: =SUM('13_Governance_Change_Mgmt'!G5:G40) | D17: =SUM('13_Governance_Change_Mgmt'!H5:H40) | E17: =IFERROR(D17/C17,0)
A18: 14_Claude_Code_Parity | B18: Claude Code → Hermes Parity | C18: =SUM('14_Claude_Code_Parity'!G5:G46) | D18: =SUM('14_Claude_Code_Parity'!H5:H46) | E18: =IFERROR(D18/C18,0)
A19: 15_Productivity_And_Acceptance | B19: Productivity & Acceptance Testing | C19: =SUM('15_Productivity_And_Acceptance'!G5:G46) | D19: =SUM('15_Productivity_And_Acceptance'!H5:H46) | E19: =IFERROR(D19/C19,0)
A20: GRAND TOTAL | C20: =SUM(C5:C19) | D20: =SUM(D5:D19) | E20: =IFERROR(D20/C20,0)
A22: FINISH LINE
A23: Hermes is 'fully realized' when ALL of the following are true at once — not just an overall percentage:
A24: 1. Grand Total % Complete above is 100%, or every remaining open row has a deliberate, written decision to leave it for later.
A25: 2. 03_Model_Routing_Resilience row MR-05 (WireGuard-down fire drill) is Done — this is the actual proof of the core promise.
A26: 3. 02_Identity_Memory rows IM-01 through IM-04 are Done — same Hermes, every interface, every location.
A27: 4. 14_Claude_Code_Parity row CCP-12 is Done — Hermes can maintain this project itself, so Claude Code's bootstrap role actually ends, not just gets described as temporary.
A28: 5. Only then: 11_Cost_Subscriptions CS-03 (cancel Claude Pro) gets executed.
A30: LEGACY GOALS (catalog G1-G9) MAPPED TO THIS WORKBOOK
A31: Goal | B31: Catalog status | C31: Detail
A33: G1 — Hermes <-> local model, one real exchange | B33: in_progress | C33: Required: confirmed reachable + one real exchange with the local model. Lives in 03_Model_Routing_Resilience; will need re-verification once 07_Local_Inference's runtime changes.
A34: G2 — local runtime serving multiple models concurrently | B34: done (stale) | C34: Required: verified on Ollama, multiple qwen3-vl variants loaded. Lives in 07_Local_Inference LI-03/LI-04 — must be re-proven on whichever runtime replaces Ollama.
A35: G3 — VPS provisioned, hermes serve running | B35: done | C35: Required: box up, agent process live. Lives in 01_Core_Runtime CR-01 to CR-03.
A36: G4 — WireGuard tunnel, LAN reachable from VPS | B36: done | C36: Required: tunnel + subnet routing, verified end-to-end. Lives in 06_Home_Network_Boundary HN-01/HN-02.
A37: G5 — ChatGPT Plus linked, Codex used for real task | B37: done | C37: Required: native link+code flow, one real coding task. Lives in 03_Model_Routing_Resilience MR-01.
A38: G6 — Hermes Desktop on laptop, same experience 2 locations | B38: not_started | C38: Required: Desktop pointed at VPS backend, proven identical from two places. Lives in 08_Interfaces_Access IA-03/IA-04, blocked on 02_Identity_Memory IM-03.
A39: G7 — Telegram wired up | B39: not_started | C39: Required: a real messaging channel on top of hermes-gateway. Lives in 08_Interfaces_Access IA-05.
A40: G8 — local-first routing verified end-to-end | B40: not_started (likely already true, never marked) | C40: Required: one prompt stays local, one escalates, both observed. The router-llm-as-judge-rebuild-2026-09-28 catalog entry already shows this happened — update the catalog goal's status field to match.
A41: G9 — Claude Pro canceled | B41: not_started | C41: Required: cancel once ChatGPT Plus/Codex covers the same ground. Lives in 11_Cost_Subscriptions CS-03 — the literal finish line.

Sheet 01_Core_Runtime
A1: Hermes Core Runtime
A2: What IS Hermes — must run on hermes-vps only, never on a home box or a laptop.
A4: ID | B4: Feature | C4: Description (execution level) | D4: Must Live On | E4: Status | F4: Evidence / Location | G4: Points | H4: Points Earned | I4: Owner Role | J4: Notes / Next Action
A5: CR-01 | B5: VPS provisioned | C5: Vultr High Performance AMD, Dallas TX — 2 vCPU / 4GB RAM / 100GB NVMe. | D5: Hermes-VPS | E5: Done | F5: hermes-vps live host | G5: 5 | H5: =IF(E5="Done",G5,IF(E5="Partial",G5*0.5,0)) | I5: Platform/SRE
A6: CR-02 | B6: HermesAgent installed on a supported channel | C6: Originally v0.19.0 via pip/uv-tool (unsupported channel, 7 versions behind, vulnerable to CVE-2026-71963 RCE). Migrated 2026-09-29 to the supported install.sh/git channel, now v0.21.5+ — RCE fixed, all dependency CVEs cleared, re-verified end-to-end post-migration. | D6: Hermes-VPS | E6: Done | F6: hermes-migrated-to-supported-install-2026-09-29 | G6: 5 | H6: =IF(E6="Done",G6,IF(E6="Partial",G6*0.5,0)) | I6: Platform/SRE
A7: CR-03 | B7: hermes-gateway running persistently | C7: systemd service, survives reboot, no login dependency. | D7: Hermes-VPS | E7: Done | F7: hermes-gateway.service (system-level unit, /etc/systemd/system, multi-user.target.wants) + real reboot 2026-10-05 17:5x UTC: active again at 17:57:00 with no login session (who=empty), dashboard HTTP 302 reachable | G7: 8 | H7: =IF(E7="Done",G7,IF(E7="Partial",G7*0.5,0)) | I7: Platform/SRE | J7: VERIFIED 2026-10-05: confirmed it's a system-level unit (not systemctl --user), so Linger was not actually load-bearing here (enabled it anyway on hermes user, harmless). Performed a real `reboot` of hermes-vps; service came back active automatically with zero logged-in sessions, dashboard responded post-boot. Reboot survival genuinely confirmed, not just systemctl status.
A8: CR-04 | B8: VPS firewall active | C8: Real firewall rules in place (previously none at all). | D8: Hermes-VPS | E8: Done | F8: hermes-vps ufw/iptables | G8: 8 | H8: =IF(E8="Done",G8,IF(E8="Partial",G8*0.5,0)) | I8: Security Reviewer
A9: CR-05 | B9: Docker + Dokploy installed | C9: Dokploy's own Traefik disabled to avoid conflicting with Caddy on 80/443. | D9: Hermes-VPS | E9: Done | F9: hermes-vps, Dokploy panel :3000 localhost-only | G9: 8 | H9: =IF(E9="Done",G9,IF(E9="Partial",G9*0.5,0)) | I9: Platform/SRE
A10: CR-06 | B10: Dokploy admin credential in vault | C10: Panel login currently wherever it was set at install, not confirmed migrated. | D10: Hermes-VPS | E10: Done | F10: vault: hermes-vps-dokploy-admin (mark.stephen.guy@gmail.com), first-run signup completed 2026-10-06, session verified via /api/auth/get-session | G10: 5 | H10: =IF(E10="Done",G10,IF(E10="Partial",G10*0.5,0)) | I10: Secrets Custodian | J10: Dokploy had zero users - completed first-run signup via its /api/auth/sign-up/email API directly, verified session is valid.
A11: CR-07 | B11: Dokploy exercised end-to-end | C11: Prove Hermes can actually deploy/manage a real container via Dokploy, not just have it installed. | D11: Hermes-VPS | E11: Done | F11: Dokploy project 'hermes-cr07-test' -> application 'cr07-throwaway' -> docker image hello-world:latest, deployed as a real Swarm service (docker service ls confirmed), deployment status 'done', then deleted via API (application.delete + project.remove). | G11: 10 | H11: =IF(E11="Done",G11,IF(E11="Partial",G11*0.5,0)) | I11: Platform/SRE | J11: Exercised via Dokploy's tRPC API directly (project.create -> application.create -> saveDockerProvider -> deploy), not Hermes's own terminal tool (which runs in an ephemeral sandboxed container with no docker access - confirmed during CR-08 attempt). Cleaned up immediately after confirming.
A12: CR-08 | B12: Hermes-hosted web presence | C12: Hermes deploys and serves a web page it built itself — the literal 'agent can host a web page' capability from ARCHITECTURE.md. | D12: Hermes-VPS | E12: Not Started | G12: 10 | H12: =IF(E12="Done",G12,IF(E12="Partial",G12*0.5,0)) | I12: Hermes Design Specialist
A13: CR-09 | B13: hermes-vps registered in catalog hosts/services tables | C13: Currently only described in free-text entities + ARCHITECTURE.md — no structured row, so infra tooling has zero visibility into VPS state. | D13: Hermes-VPS | E13: Done | F13: catalog host id 7 (hermes-vps) + 5 service rows (hermes-gateway, complexity-router, Caddy, Dokploy, WireGuard wg0) added 2026-10-06 | G13: 8 | H13: =IF(E13="Done",G13,IF(E13="Partial",G13*0.5,0)) | I13: Platform/SRE | J13: Registered via PostgREST. Dokploy service row notes CR-06 as the remaining gap (admin credential not recoverable from docker env/logs).
A14: CR-10 | B14: OS/package patch cadence defined | C14: No documented policy for when/how the VPS gets security patches. | D14: Hermes-VPS | E14: Done | F14: systemctl is-enabled unattended-upgrades = enabled; /etc/apt/apt.conf.d/20auto-upgrades has Update-Package-Lists=1, Unattended-Upgrade=1 | G14: 5 | H14: =IF(E14="Done",G14,IF(E14="Partial",G14*0.5,0)) | I14: Platform/SRE | J14: Already active on the Vultr image by default - verified 2026-10-06, not something that needed building.
A15: CR-11 | B15: hermes-agent version pin + upgrade process | C15: What triggers an upgrade, how it's tested before cutover. | D15: Hermes-VPS | E15: Done | F15: policy logged to catalog 2026-10-06 | G15: 5 | H15: =IF(E15="Done",G15,IF(E15="Partial",G15*0.5,0)) | I15: Platform/SRE | J15: POLICY: upgrade is manual, triggered only when a specific needed fix/feature requires it (not merely 'commits behind'). After hermes update: re-run hermes doctor + hermes security audit, confirm hermes-gateway and complexity-router still active, before considering the upgrade final.
A16: CR-12 | B16: Resource headroom monitored | C16: 4GB RAM is tight once more MCP servers/venvs stack up — needs a ceiling check, not just hope. | D16: Hermes-VPS | E16: Done | F16: hermes-memcheck.timer + .service (systemd, every 15min, logs via logger if available memory <500MB). Current baseline 2026-10-06: 257MB free / 1.7GB available of 3.8GB total, 600MB already in swap. | G16: 5 | H16: =IF(E16="Done",G16,IF(E16="Partial",G16*0.5,0)) | I16: Platform/SRE | J16: Lightweight ceiling check, not full alerting (that's OB-02's job - cross-referenced). Headroom is confirmed genuinely tight, not hypothetical.
A17: CR-13 | B17: config.yaml edits via comment-preserving method | C17: A prior full parse+dump via PyYAML silently stripped all comments; switch to ruamel.yaml or targeted text edits. Found 2026-10-05: dashboard has a form-based Config editor (150+ fields, export/import JSON) -- may sidestep the comment-stripping problem entirely since it's not a full YAML parse+dump. Untested whether it preserves comments on fields it doesn't touch. See D6_Web_Dashboard. | D17: Hermes-VPS | E17: Done | F17: hermes config set/get used exclusively throughout 2026-10-05/06 session (CR-17, SH-04, security.protected_instruction_files toggle) - never a raw PyYAML parse+dump | G17: 3 | H17: =IF(E17="Done",G17,IF(E17="Partial",G17*0.5,0)) | I17: Platform/SRE | J17: Confirmed in practice: hermes's own config CLI is the safe method, sidesteps the comment-stripping incident entirely since it's not a full-file parse+rewrite.
A18: CR-14 | B18: Staged config changes | C18: A way to validate a config.yaml change before it hits the live gateway (even a dry-run diff), so a bad edit doesn't take down the running agent. Found 2026-10-05: Checkpoints feature auto-snapshots before file writes (shadow git repo) and the Config page has reset-to-defaults/export-JSON -- may partly cover 'validate before it hits the live gateway' without custom tooling. See D6_Web_Dashboard. | D18: Hermes-VPS | E18: Done | F18: hermes checkpoints status confirmed real: shadow git repo auto-snapshots before write_file/patch/terminal calls (/home/hermes/.hermes/checkpoints) | G18: 5 | H18: =IF(E18="Done",G18,IF(E18="Partial",G18*0.5,0)) | I18: Hermes Design Specialist | J18: Built-in mechanism satisfies this without custom tooling, per the D6_Web_Dashboard lead. hermes checkpoints list/status/prune available for recovery.
A19: CR-15 | B19: Sister's Hermes — separate VPS provisioned | C19: Decided 2026-10-04: full separation, not a restricted-user account on this instance, so memory/context never bleeds between the two. Vultr High Performance AMD, 1 vCPU / 2GB RAM / 50GB NVMe, $12/mo, HermesAgent marketplace image — same pattern as hermes-vps. | D19: Hermes-VPS | E19: Not Started | F19: hermes-sister-separate-agent-2026-10-04 | G19: 8 | H19: =IF(E19="Done",G19,IF(E19="Partial",G19*0.5,0)) | I19: Product Owner (Mark) | J19: DEFERRED 2026-10-06 per explicit user decision: Sister's Hermes is put off until this Hermes instance is complete. Not abandoned, intentionally sequenced after this project's own finish line.
A20: CR-16 | B20: Sister's Hermes — local-model access decided | C20: Open question from the planning conversation: does her instance get access to w_workstation's local model, or stay Codex/cloud-only? One RTX A4000 can't serve two simultaneous agents without one waiting on the other. | D20: Either / Bridge | E20: Not Started | G20: 3 | H20: =IF(E20="Done",G20,IF(E20="Partial",G20*0.5,0)) | I20: Product Owner (Mark) | J20: DEFERRED 2026-10-06 per explicit user decision: Sister's Hermes is put off until this Hermes instance is complete. Not abandoned, intentionally sequenced after this project's own finish line.
A21: CR-17 | B21: Terminal backend: Docker — locked in | C21: LOCKED 2026-10-04: terminal.backend=docker, not local. Directly relevant to HN-05/SH-02 (gateway shell exposure) — switching off 'local' sandboxes every command Hermes runs in a container instead of executing directly on the VPS, containing blast radius even before the allowlist fix lands. Docker's already installed on hermes-vps for Dokploy. | D21: Hermes-VPS | E21: Done | F21: config.yaml: terminal.backend=docker, terminal.container_memory=1024 (box is 3.8GiB total); hermes user added to docker group, gateway restarted, 'hermes doctor' confirms Docker (daemon running) | G21: 8 | H21: =IF(E21="Done",G21,IF(E21="Partial",G21*0.5,0)) | I21: Security Reviewer | J21: APPLIED 2026-10-05: set terminal.backend=docker and terminal.container_memory=1024 (down from the 5120 default that exceeded the box's 4GB RAM). hermes doctor flagged Docker as unreachable after the config change -- root cause was the hermes user not being in the docker group (permission denied on /var/run/docker.sock). Fixed with usermod -aG docker hermes + systemctl restart hermes-gateway to pick up the new group membership. Re-ran hermes doctor: Docker (daemon running) now green.
A22: CR-18 | B22: SSH access to hermes-vps catalogued for execution | C22: DECIDED 2026-10-05: user chose to give Claude Code real SSH access (over the SSH access option) rather than routing execution through the web dashboard's Chat. No SSH credential exists in the vault yet -- hermes-vps was also confirmed absent from the catalog hosts table entirely (CR-09). Needed: host/IP, port, username, key or password. | D22: Hermes-VPS | E22: Done | F22: vault secret hermes-vps-ssh (root@207.148.2.224, same key as default ~/.ssh/id_ed25519) | G22: 5 | H22: =IF(E22="Done",G22,IF(E22="Partial",G22*0.5,0)) | I22: Platform/SRE | J22: Vaulted 2026-10-05 before any execution work began. SSH tested and used continuously since.
H23: =IF(E22="Done",G22,IF(E22="Partial",G22*0.5,0))
H24: =IF(E23="Done",G23,IF(E23="Partial",G23*0.5,0))
H25: =IF(E24="Done",G24,IF(E24="Partial",G24*0.5,0))
H26: =IF(E25="Done",G25,IF(E25="Partial",G25*0.5,0))
H27: =IF(E26="Done",G26,IF(E26="Partial",G26*0.5,0))
H28: =IF(E27="Done",G27,IF(E27="Partial",G27*0.5,0))
H29: =IF(E28="Done",G28,IF(E28="Partial",G28*0.5,0))
H30: =IF(E29="Done",G29,IF(E29="Partial",G29*0.5,0))
H31: =IF(E30="Done",G30,IF(E30="Partial",G30*0.5,0))
H32: =IF(E31="Done",G31,IF(E31="Partial",G31*0.5,0))
H33: =IF(E32="Done",G32,IF(E32="Partial",G32*0.5,0))
H34: =IF(E33="Done",G33,IF(E33="Partial",G33*0.5,0))
... H52: =IF(E51="Done",G51,IF(E51="Partial",G51*0.5,0))
B54: TAB TOTAL (includes blank headroom rows above for future additions) | G54: =SUM(G5:G51) | H54: =SUM(H5:H51) | I54: =IFERROR(TEXT(H53/G53,"0%")&" complete","0% complete")

Sheet 02_Identity_Memory
A1: Identity & Memory Continuity
A2: The thing that makes 'Hermes away from home' the same Hermes as 'at home.'
A4: ID | B4: Feature | C4: Description (execution level) | D4: Must Live On | E4: Status | F4: Evidence / Location | G4: Points | H4: Points Earned | I4: Owner Role | J4: Notes / Next Action
A5: IM-01 | B5: SOUL.md committed to hermes-vps | C5: CORRECTION 2026-10-04: an earlier pass here wrongly claimed SOUL.md wasn't real — it is, and it's distinct from MEMORY.md (see IM-09). Lives at ~/.hermes/SOUL.md, 2,200-char cap, defines WHO the agent is — persona, tone, values, boundaries, judgment style. First slot in the system prompt. Auto-created with a generic default if missing; the version drafted in conversation was never actually written to the box. | D5: Hermes-VPS | E5: Done | F5: ~/.hermes/SOUL.md (1660 bytes), confirmed correct path by hermes doctor: '✓ SOUL.md exists (persona configured)' | G5: 10 | H5: =IF(E5="Done",G5,IF(E5="Partial",G5*0.5,0)) | I5: Hermes Design Specialist | J5: Path confirmed correct via doctor source (doctor_state.py: soul_path = hermes_home / 'SOUL.md', top-level).
A6: IM-02 | B6: USER.md committed to hermes-vps | C6: User profile/preferences, 1,375-char cap, distinct from both SOUL.md and MEMORY.md. Same status — drafted, never committed. | D6: Hermes-VPS | E6: Done | F6: ~/.hermes/memories/USER.md (1036 bytes, general-only now) + separate 'Prograder Price Changes' hermes project (p_9d13c5a9, /home/hermes/prograder-price-changes/NOTES.md) holding the project-specific fact that was previously mixed into USER.md | G6: 10 | H6: =IF(E6="Done",G6,IF(E6="Partial",G6*0.5,0)) | I6: Hermes Design Specialist | J6: PRINCIPLE established 2026-10-06 per user: general files (SOUL/USER/MEMORY) are about Hermes in general, never project-specific. Found project-specific content (Prograder price-change work preferences) mixed into USER.md - created a proper hermes project for it and moved the fact there, left only general facts in USER.md.
A7: IM-03 | B7: Single conversation/session store confirmed | C7: Unverified whether every interface reads/writes one store or each starts disconnected. | D7: Hermes-VPS | E7: Not Started | G7: 10 | H7: =IF(E7="Done",G7,IF(E7="Partial",G7*0.5,0)) | I7: Hermes Design Specialist | J7: Decides whether G6 is even architecturally possible
A8: IM-04 | B8: Cross-interface continuity proven | C8: Web UI, Hermes Desktop, and (eventually) Telegram all resume the same memory, not three separate Hermeses. | D8: Hermes-VPS | E8: Not Started | G8: 10 | H8: =IF(E8="Done",G8,IF(E8="Partial",G8*0.5,0)) | I8: Hermes Design Specialist | J8: Found 2026-10-05: practical template ready -- 4 sections (Soul/Voice/Operations/Restrictions), 50-80 lines (~400-800 tokens/turn), official starter pattern available. hermes prompt-size shows actual token cost once written. This was the main blocker on this row -- ready to draft and commit. See D8_Advanced_Reference.
A9: IM-05 | B9: Extended memory provider: Hindsight — locked in | C9: LOCKED 2026-10-04, number CORRECTED 2026-10-05: after comparing all 8 official Hermes memory plugins (Hindsight, ByteRover, Supermemory, Mem0, Honcho, OpenViking, Holographic, RetainDB) plus Mnemosyne, Hindsight had the best independently-reproduced LongMemEval result. The '94.6%' originally cited here was a misread of one sub-metric (single-session-assistant) off the vectorize-io/hindsight-benchmarks leaderboard — Hindsight's actual overall LongMemEval score is 91.4% (Gemini-3 variant) / 89.0% (OSS-120B). Checked against Mastra Observational Memory's 94.87% counter-claim (which would outrank it): Mastra's number is vendor-self-reported on their own site, not independently reproduced, so it doesn't clear the same bar ByteRover's LoCoMo number was already rejected for -- decision stands, only the cited figure was wrong. Its reflect operation also directly matches the actual requirement: broad scope ('anything is fair game,' Hermes = main AI tool going forward) but genuinely curated ('remembering everything means remembering nothing') -- reflect reasons across all stored memories to produce one synthesized answer, not a ranked dump; retain does entity resolution so facts link to canonical people/projects. Local Docker mode, own Postgres, no cloud dependency -- could share a database with the migrated catalog/vault (SV-15). | D9: Hermes-VPS | E9: Partial | F9: hermes-hindsight-benchmark-correction-2026-10-05 | G9: 8 | H9: =IF(E9="Done",G9,IF(E9="Partial",G9*0.5,0)) | I9: Hermes Design Specialist | J9: Decided, not yet deployed. Depends on SV-15 landing first for the shared-database option Found 2026-10-05 (see D4_Crons_System): cron-run sessions pass skip_memory=True -- Hindsight will NOT see or inform cron job output unless that changes. Not a blocker, just dont assume cron jobs get interactive-chat memory context.
A10: IM-06 | B10: Hermes runtime-memory backup | C10: Parallel to export_catalog_memory.py, but for whatever Hermes itself remembers once IM-03 exists. | D10: Hermes-VPS | E10: Not Started | G10: 5 | H10: =IF(E10="Done",G10,IF(E10="Partial",G10*0.5,0)) | I10: Platform/SRE
A11: IM-07 | B11: Memory retention/privacy policy | C11: The built-in system already has a real policy, found 2026-10-04: facts/corrections persisted aggressively, preferences/skills only once they prove themselves, nothing sensitive ever. Capture is agent-judged, not automatic — periodic self-prompts ask 'should I persist this?' (solves humans forgetting to flag what matters). Still undefined: what the SAME policy should be for an extended provider (IM-05) once it exists, which has no built-in character cap forcing curation the way MEMORY.md's 2,200-char limit does. | D11: N/A (process/doc) | E11: Partial | F11: hermes-agent docs: persistent memory | G11: 3 | H11: =IF(E11="Done",G11,IF(E11="Partial",G11*0.5,0)) | I11: Hermes Design Specialist
A12: IM-08 | B12: Identity consistency test | C12: Ask 'who are you' from two different interfaces/locations, confirm identical answer, as an actual verification step not an assumption. | D12: N/A (process/doc) | E12: Not Started | G12: 5 | H12: =IF(E12="Done",G12,IF(E12="Partial",G12*0.5,0)) | I12: Hermes Design Specialist
A13: IM-09 | B13: MEMORY.md committed to hermes-vps | C13: Distinct from SOUL.md (IM-01): MEMORY.md holds WHAT the agent has learned — environment facts, conventions, discovered workarounds — not who it is. Same 2,200-char cap; on overflow the agent must consolidate/remove entries before adding more (some nuance gets lost in that process). Human-prunable by hand-editing the file directly; hermes memory compress --older-than 30d also exists for session-level compression. | D13: Hermes-VPS | E13: Not Started | F13: ~/.hermes/memories/MEMORY.md does not exist yet - confirmed via hermes doctor: 'MEMORY.md not created yet (will be created when the agent first writes a memory)' | G13: 8 | H13: =IF(E13="Done",G13,IF(E13="Partial",G13*0.5,0)) | I13: Hermes Design Specialist | J13: CORRECTED 2026-10-06: this is NOT a static file to hand-author - it's populated by the agent itself as it learns facts during real use (same mechanism as memories/USER.md, which already has real entries). My earlier hand-written MEMORY.md went to the wrong path AND the wrong model (static doc vs agent-grown store) - removed. Closes naturally once Hermes is actually used, not by seeding it manually.
H14: =IF(E14="Done",G14,IF(E14="Partial",G14*0.5,0))
H15: =IF(E15="Done",G15,IF(E15="Partial",G15*0.5,0))
H16: =IF(E16="Done",G16,IF(E16="Partial",G16*0.5,0))
H17: =IF(E17="Done",G17,IF(E17="Partial",G17*0.5,0))
H18: =IF(E18="Done",G18,IF(E18="Partial",G18*0.5,0))
H19: =IF(E19="Done",G19,IF(E19="Partial",G19*0.5,0))
H20: =IF(E20="Done",G20,IF(E20="Partial",G20*0.5,0))
H21: =IF(E21="Done",G21,IF(E21="Partial",G21*0.5,0))
H22: =IF(E22="Done",G22,IF(E22="Partial",G22*0.5,0))
H23: =IF(E23="Done",G23,IF(E23="Partial",G23*0.5,0))
H24: =IF(E24="Done",G24,IF(E24="Partial",G24*0.5,0))
H25: =IF(E25="Done",G25,IF(E25="Partial",G25*0.5,0))
... H43: =IF(E43="Done",G43,IF(E43="Partial",G43*0.5,0))
B45: TAB TOTAL (includes blank headroom rows above for future additions) | G45: =SUM(G5:G43) | H45: =SUM(H5:H43) | I45: =IFERROR(TEXT(H45/G45,"0%")&" complete","0% complete")

Sheet 03_Model_Routing_Resilience
A1: Model, Provider & Resilience
A2: Codex must be a COMPLETE Hermes on its own — local inference is an accelerant, never a dependency.
A4: ID | B4: Feature | C4: Description (execution level) | D4: Must Live On | E4: Status | F4: Evidence / Location | G4: Points | H4: Points Earned | I4: Owner Role | J4: Notes / Next Action
A5: MR-01 | B5: Codex linked via native link+code flow | C5: openai-codex / gpt-5.6-sol, via existing ChatGPT Plus — confirmed working for a real coding task. | D5: Hermes-VPS | E5: Done | F5: hermes-vps config.yaml providers | G5: 8 | H5: =IF(E5="Done",G5,IF(E5="Partial",G5*0.5,0)) | I5: Model/Routing Engineer
A6: MR-02 | B6: Judge-based local-vs-escalate routing live | C6: complexity_router.py replaced keyword heuristics with an LLM-as-judge call. | D6: Hermes-VPS | E6: Done | F6: complexity-router.service, 127.0.0.1:11500 | G6: 10 | H6: =IF(E6="Done",G6,IF(E6="Partial",G6*0.5,0)) | I6: Model/Routing Engineer
A7: MR-03 | B7: Hard gates: vision + bounded-task bypass | C7: has_image() forces local (Codex rejects image_url with HTTP 400); max_tokens<=32 bypasses the judge entirely for Smart Approvals. | D7: Hermes-VPS | E7: Done | F7: scripts/complexity_router.py | G7: 8 | H7: =IF(E7="Done",G7,IF(E7="Partial",G7*0.5,0)) | I7: Model/Routing Engineer
A8: MR-04 | B8: fallback_model escalation verified live | C8: 503 from the router correctly triggers Hermes's native fallback_model retry onto Codex. | D8: Hermes-VPS | E8: Done | F8: hermes-vps logs, 2026-09-27 verification | G8: 8 | H8: =IF(E8="Done",G8,IF(E8="Partial",G8*0.5,0)) | I8: Model/Routing Engineer
A9: MR-05 | B9: WireGuard-down fire drill (model only) | C9: Nobody has pulled the tunnel mid-conversation and confirmed Hermes still answers via Codex automatically. 'Fails open to local' on a judge timeout is not proven to hold when the underlying connection itself is down. Scoped to the model/routing path only — see 05_Secrets_Vault SV-14 for the matching gap in catalog/vault reachability. | D9: Hermes-VPS | E9: Not Started | G9: 15 | H9: =IF(E9="Done",G9,IF(E9="Partial",G9*0.5,0)) | I9: Model/Routing Engineer | J9: This is the exact guarantee the user is building toward
A10: MR-06 | B10: Health check / circuit breaker on local provider | C10: Proactively mark local down instead of relying on per-request timeout-and-retry. | D10: Hermes-VPS | E10: Not Started | G10: 10 | H10: =IF(E10="Done",G10,IF(E10="Partial",G10*0.5,0)) | I10: Model/Routing Engineer
A11: MR-07 | B11: Per-turn backend indicator | C11: Surface/log which backend (local vs Codex) actually answered each turn. | D11: Hermes-VPS | E11: Not Started | G11: 5 | H11: =IF(E11="Done",G11,IF(E11="Partial",G11*0.5,0)) | I11: Observability
A12: MR-08 | B12: Local runtime/model finalized | C12: See 07_Local_Inference — this row just tracks the routing-layer consequence of that decision. | D12: Home-Network | E12: Not Started | G12: 5 | H12: =IF(E12="Done",G12,IF(E12="Partial",G12*0.5,0)) | I12: Model/Routing Engineer
A13: MR-09 | B13: G8 criterion re-verified on new runtime | C13: Old proof (Ollama) will be stale the moment the runtime changes — must re-run 'one stays local, one escalates, both observed' after cutover. | D13: Either / Bridge | E13: Not Started | G13: 8 | H13: =IF(E13="Done",G13,IF(E13="Partial",G13*0.5,0)) | I13: Model/Routing Engineer
A14: MR-10 | B14: Codex spend ceiling / circuit breaker | C14: No cap or alert exists if Codex usage spikes — relevant once it's the sole fallback. | D14: Hermes-VPS | E14: Not Started | G14: 5 | H14: =IF(E14="Done",G14,IF(E14="Partial",G14*0.5,0)) | I14: Product Owner (Mark)
A15: MR-13 | B15: Vultr Serverless Inference fallback model: DeepSeek-V4-Flash — locked in | C15: LOCKED 2026-10-04: cheapest of the 8 pre-configured models ($0.30/M input, $1.00/M output), fast, general-purpose — right fit for a middle tier meant to be cheap overflow capacity, not a second Codex. Already pre-configured/credentialed on hermes-vps; just needs an explicit fallback_providers entry in config.yaml. | D15: Hermes-VPS | E15: Partial | F15: hermes-five-provider-choices-locked-2026-10-04 | G15: 5 | H15: =IF(E15="Done",G15,IF(E15="Partial",G15*0.5,0)) | I15: Model/Routing Engineer | J15: No three-tier routing logic exists yet (judge only knows local-vs-Codex) — this model is configured but not yet reachable by the router
A16: MR-11 | B16: Retry/backoff policy documented | C16: Transient local error vs. hard failure should not be handled identically. | D16: Hermes-VPS | E16: Not Started | G16: 3 | H16: =IF(E16="Done",G16,IF(E16="Partial",G16*0.5,0)) | I16: Model/Routing Engineer
A17: MR-12 | B17: Routing-decision log retention policy | C17: complexity_router.log exists and records every verdict, but nothing rotates or retains it deliberately. | D17: Hermes-VPS | E17: Partial | F17: /home/hermes/.hermes/logs/complexity_router.log | G17: 3 | H17: =IF(E17="Done",G17,IF(E17="Partial",G17*0.5,0)) | I17: Observability
H18: =IF(E18="Done",G18,IF(E18="Partial",G18*0.5,0))
H19: =IF(E19="Done",G19,IF(E19="Partial",G19*0.5,0))
H20: =IF(E20="Done",G20,IF(E20="Partial",G20*0.5,0))
H21: =IF(E21="Done",G21,IF(E21="Partial",G21*0.5,0))
H22: =IF(E22="Done",G22,IF(E22="Partial",G22*0.5,0))
H23: =IF(E23="Done",G23,IF(E23="Partial",G23*0.5,0))
H24: =IF(E24="Done",G24,IF(E24="Partial",G24*0.5,0))
H25: =IF(E25="Done",G25,IF(E25="Partial",G25*0.5,0))
H26: =IF(E26="Done",G26,IF(E26="Partial",G26*0.5,0))
H27: =IF(E27="Done",G27,IF(E27="Partial",G27*0.5,0))
H28: =IF(E28="Done",G28,IF(E28="Partial",G28*0.5,0))
H29: =IF(E29="Done",G29,IF(E29="Partial",G29*0.5,0))
... H47: =IF(E47="Done",G47,IF(E47="Partial",G47*0.5,0))
B49: TAB TOTAL (includes blank headroom rows above for future additions) | G49: =SUM(G5:G47) | H49: =SUM(H5:H47) | I49: =IFERROR(TEXT(H49/G49,"0%")&" complete","0% complete")

Sheet 04_Tool_MCP_Layer
A1: Tool / MCP Capability Layer
A2: Every network resource as an agent capability — and ONE deployment per capability, not one per environment.
A4: ID | B4: Feature | C4: Description (execution level) | D4: Must Live On | E4: Status | F4: Evidence / Location | G4: Points | H4: Points Earned | I4: Owner Role | J4: Notes / Next Action
A5: TM-01 | B5: catalog_mcp.py — VPS-only | C5: 6 tools (get_entities, get_hosts, get_services, add_entity, add_relation, graph_recall), isolated venv, verified live. | D5: Hermes-VPS | E5: Done | F5: /home/hermes/.hermes/mcp_servers/catalog/ | G5: 8 | H5: =IF(E5="Done",G5,IF(E5="Partial",G5*0.5,0)) | I5: Platform/SRE
A6: TM-02 | B6: search_mcp.py — VPS-only, web_search reliable | C6: Brave API-backed, verified via real hermes -z call. | D6: Hermes-VPS | E6: Done | F6: /home/hermes/.hermes/mcp_servers/search/ | G6: 8 | H6: =IF(E6="Done",G6,IF(E6="Partial",G6*0.5,0)) | I6: Platform/SRE
A7: TM-03 | B7: fetch_page tool-recognition fixed | C7: Model inconsistently recognizes the tool exists across invocation modes (chat -q vs -z --cli) — root cause not isolated yet. | D7: Hermes-VPS | E7: Not Started | F7: scripts/search_mcp.py — open bug | G7: 5 | H7: =IF(E7="Done",G7,IF(E7="Partial",G7*0.5,0)) | I7: Model/Routing Engineer
A8: TM-04 | B8: infra_mcp.py — Salt wrapping | C8: salt_run / salt_minion_status, auto-refreshing auth token, scoped eauth user. | D8: Hermes-VPS | E8: Done | F8: hermes-vps config.yaml mcp_servers.infra | G8: 8 | H8: =IF(E8="Done",G8,IF(E8="Partial",G8*0.5,0)) | I8: Home-Network Liaison
A9: TM-05 | B9: infra_mcp.py — MeshCentral + Beszel wrapping | C9: Original goal was a unified Salt+MeshCentral+Beszel surface; only Salt got built. | D9: Hermes-VPS | E9: Not Started | F9: scripts/infra_mcp.py | G9: 8 | H9: =IF(E9="Done",G9,IF(E9="Partial",G9*0.5,0)) | I9: Home-Network Liaison
A10: TM-06 | B10: vault_mcp.py consolidated to ONE deployment | C10: Currently 4 independent copies/venvs: hermes-vps, laptop Claude Code .mcp.json, laptop Codex config.toml, and a project-scoped .codex/config.toml. Same tool, four things to keep in sync by hand. Scored under 05_Secrets_Vault SV-12 — this row is the tooling-side cross-reference, not separately weighted. | D10: Hermes-VPS | E10: Not Started | F10: 4x — scored at SV-12 | G10: 0 | H10: =IF(E10="Done",G10,IF(E10="Partial",G10*0.5,0)) | I10: Hermes Design Specialist | J10: Decide: single VPS-only server all clients call remotely, or explicitly-temporary local copies with a documented sunset
A11: TM-07 | B11: Nous native Tool Gateway configured | C11: CORRECTED 2026-10-05: this is 4 tools only (web_search/Firecrawl, image_gen/FAL, TTS/OpenAI, browser automation/Browser Use), opt-in per-tool via use_gateway:true, requires a PAID Nous Portal subscription (not available on free tier for these 4). The earlier '5 sandboxed exec backends' description was wrong -- that's actually the terminal tool's 7 backends (local/docker/ssh/singularity/modal/daytona/vercel_sandbox), a separate system already covered by CR-17. See D8_Advanced_Reference. | D11: Hermes-VPS | E11: Not Started | G11: 8 | H11: =IF(E11="Done",G11,IF(E11="Partial",G11*0.5,0)) | I11: Platform/SRE | J11: Given Obscura + existing web-search/TTS providers already locked in, likely not worth a paid Portal subscription just for this.
A12: TM-08 | B12: Remote-desktop capability fully enrolled | C12: MeshCentral (had zero devices connected since July) was replaced by Apache Guacamole 2026-10-01 — RDP/SSH native, no agents needed. w_workstation proven end-to-end; other hosts not yet confirmed through it. | D12: Home-Network | E12: Partial | F12: guacamole-deployed-fileserver-2026-10-01 | G12: 5 | H12: =IF(E12="Done",G12,IF(E12="Partial",G12*0.5,0)) | I12: Home-Network Liaison
A13: TM-09 | B13: Unified admin surface for mixed local ecosystem | C13: Open user ask (2026-09-30): broader than Salt alone, MCP-accessible. | D13: Home-Network | E13: Not Started | G13: 8 | H13: =IF(E13="Done",G13,IF(E13="Partial",G13*0.5,0)) | I13: Home-Network Liaison
A14: TM-10 | B14: Playbook: promote a home capability to a Hermes tool | C14: A repeatable, documented process — not ad hoc each time. | D14: N/A (process/doc) | E14: Not Started | G14: 5 | H14: =IF(E14="Done",G14,IF(E14="Partial",G14*0.5,0)) | I14: Hermes Design Specialist
A15: TM-11 | B15: Least-privilege review across all MCP credentials | C15: salt-hermes-infra is properly scoped (no wheel/runner); others not reviewed the same way. | D15: Either / Bridge | E15: Partial | G15: 5 | H15: =IF(E15="Done",G15,IF(E15="Partial",G15*0.5,0)) | I15: Security Reviewer
A16: TM-12 | B16: MCP server dependency/version pinning | C16: FastMCP version and venv contents should be reproducible, not whatever was latest at deploy time. | D16: Hermes-VPS | E16: Not Started | G16: 3 | H16: =IF(E16="Done",G16,IF(E16="Partial",G16*0.5,0)) | I16: Platform/SRE
A17: TM-13 | B17: Tool-call audit trail | C17: No record of who/what invoked which tool, when — matters once multiple agents (Hermes, Claude Code, Codex) share the same tool surface. | D17: Hermes-VPS | E17: Not Started | G17: 5 | H17: =IF(E17="Done",G17,IF(E17="Partial",G17*0.5,0)) | I17: Security Reviewer
A18: TM-14 | B18: Browser automation: Obscura — locked in | C18: LOCKED 2026-10-04: Obscura (Rust headless browser, ~30MB/instance) over local Chrome/Camofox (200-400MB+/instance — too heavy for a 4GB VPS already running several services) and cloud options (Browserbase/Browser Use, paid). Known risk, stated plainly: NOT officially supported by hermes-agent core — the integration request was closed as not planned. Only available via the community plugin hermes-plugin-obscura. | D18: Hermes-VPS | E18: Partial | F18: hermes-browser-automation-obscura-2026-10-04 | G18: 5 | H18: =IF(E18="Done",G18,IF(E18="Partial",G18*0.5,0)) | I18: Hermes Design Specialist | J18: Install: hermes plugins install SGavrl/hermes-plugin-obscura --enable. Unofficial-plugin risk accepted knowingly, not overlooked
H19: =IF(E19="Done",G19,IF(E19="Partial",G19*0.5,0))
H20: =IF(E20="Done",G20,IF(E20="Partial",G20*0.5,0))
H21: =IF(E21="Done",G21,IF(E21="Partial",G21*0.5,0))
H22: =IF(E22="Done",G22,IF(E22="Partial",G22*0.5,0))
H23: =IF(E23="Done",G23,IF(E23="Partial",G23*0.5,0))
H24: =IF(E24="Done",G24,IF(E24="Partial",G24*0.5,0))
H25: =IF(E25="Done",G25,IF(E25="Partial",G25*0.5,0))
H26: =IF(E26="Done",G26,IF(E26="Partial",G26*0.5,0))
H27: =IF(E27="Done",G27,IF(E27="Partial",G27*0.5,0))
H28: =IF(E28="Done",G28,IF(E28="Partial",G28*0.5,0))
H29: =IF(E29="Done",G29,IF(E29="Partial",G29*0.5,0))
H30: =IF(E30="Done",G30,IF(E30="Partial",G30*0.5,0))
... H48: =IF(E48="Done",G48,IF(E48="Partial",G48*0.5,0))
B50: TAB TOTAL (includes blank headroom rows above for future additions) | G50: =SUM(G5:G48) | H50: =SUM(H5:H48) | I50: =IFERROR(TEXT(H50/G50,"0%")&" complete","0% complete")

Sheet 05_Secrets_Vault
A1: Secrets & Vault
A2: If a tool needs a password, it comes from here at call time — never hardcoded, never duplicated at rest.
A4: ID | B4: Feature | C4: Description (execution level) | D4: Must Live On | E4: Status | F4: Evidence / Location | G4: Points | H4: Points Earned | I4: Owner Role | J4: Notes / Next Action
A5: SV-01 | B5: Vault backing store live | C5: Postgres secrets table, pgcrypto-encrypted, secret_get/secret_set RPCs, passcode supplied per-call only. Backing store physically lives on fileserver (Home-Network), reached by hermes-vps over the WireGuard tunnel — see SV-14 for why that matters. | D5: Home-Network | E5: Done | F5: fileserver:3003 catalog-db | G5: 8 | H5: =IF(E5="Done",G5,IF(E5="Partial",G5*0.5,0)) | I5: Secrets Custodian | J5: CLARIFIED 2026-10-05: this row is about the EXTERNAL catalog Postgres vault (pgp_sym_encrypt). Hermes ALSO has its own separate, local, Fernet-encrypted Credential Vault (~/.hermes/vault/, for browser-fill passwords) plus a distinct Credential Pools feature (multi-key rotation per provider) and an 'API Keys' dashboard page (.env management, not encrypted at rest). Four different 'vault-shaped' things now exist -- don't conflate them. See D6_Web_Dashboard.
A6: SV-02 | B6: 10 secrets migrated | C6: w_workstation-llm, w_workstation-mguy, server-mark-sudo, server-portainer-admin, hermes-vps-caddy-basic-auth, hermes-vps-dashboard-basic-auth, hermes-vps-vultr-inference-api-key, hermes-vps-brave-search-api-key, meshcentral-claude-login-token, salt-hermes-infra. | D6: Either / Bridge | E6: Done | F6: vault | G6: 10 | H6: =IF(E6="Done",G6,IF(E6="Partial",G6*0.5,0)) | I6: Secrets Custodian
A7: SV-03 | B7: DuckDNS token in vault | C7: Not yet migrated. | D7: Home-Network | E7: Not Started | G7: 3 | H7: =IF(E7="Done",G7,IF(E7="Partial",G7*0.5,0)) | I7: Secrets Custodian
A8: SV-04 | B8: NPM admin login in vault | C8: Not yet migrated. | D8: Home-Network | E8: Not Started | G8: 3 | H8: =IF(E8="Done",G8,IF(E8="Partial",G8*0.5,0)) | I8: Secrets Custodian
A9: SV-05 | B9: WordPress / MariaDB creds in vault | C9: Not yet migrated. | D9: Home-Network | E9: Not Started | G9: 3 | H9: =IF(E9="Done",G9,IF(E9="Partial",G9*0.5,0)) | I9: Secrets Custodian
A10: SV-06 | B10: AdGuard admin in vault | C10: Not yet migrated. | D10: Home-Network | E10: Not Started | G10: 3 | H10: =IF(E10="Done",G10,IF(E10="Partial",G10*0.5,0)) | I10: Secrets Custodian
A11: SV-07 | B11: Modal API key located + vaulted | C11: Location not even fully confirmed yet, separate from being in the vault. | D11: Hermes-VPS | E11: Not Started | G11: 5 | H11: =IF(E11="Done",G11,IF(E11="Partial",G11*0.5,0)) | I11: Secrets Custodian
A12: SV-08 | B12: /Dockers share plaintext .env exposure remediated | C12: Every container's real secrets (DB passwords, Portainer admin) sit on an anonymous guest-accessible SMB share, by deliberate design choice — the single largest exposure on the network and outside the vault effort entirely. | D12: Home-Network | E12: Not Started | F12: server:/Dockers (guest ok=yes) | G12: 15 | H12: =IF(E12="Done",G12,IF(E12="Partial",G12*0.5,0)) | I12: Security Reviewer | J12: Biggest single item on this whole workbook. Scored here; see 12_Security_Hardening SH-03 cross-reference
A13: SV-09 | B13: Vultr inference key removed from config.yaml plaintext | C13: In the vault now, but never confirmed the plaintext copy in providers.vultr was actually deleted rather than just duplicated. | D13: Hermes-VPS | E13: Not Started | F13: hermes-vps config.yaml | G13: 3 | H13: =IF(E13="Done",G13,IF(E13="Partial",G13*0.5,0)) | I13: Secrets Custodian
A14: SV-10 | B14: Secret rotation policy | C14: Nothing defines when/how any of the 10 vaulted secrets get rotated. | D14: N/A (process/doc) | E14: Not Started | G14: 5 | H14: =IF(E14="Done",G14,IF(E14="Partial",G14*0.5,0)) | I14: Secrets Custodian
A15: SV-11 | B15: Vault access audit log | C15: No record of who called get_secret, when, for what. | D15: Hermes-VPS | E15: Not Started | G15: 5 | H15: =IF(E15="Done",G15,IF(E15="Partial",G15*0.5,0)) | I15: Security Reviewer
A16: SV-12 | B16: Vault server consolidated to one deployment | C16: Same underlying item as 04_Tool_MCP_Layer TM-06 — scored here since it's fundamentally a secrets-handling problem, not just a tooling one. | D16: Hermes-VPS | E16: Not Started | F16: 4x deployments | G16: 12 | H16: =IF(E16="Done",G16,IF(E16="Partial",G16*0.5,0)) | I16: Hermes Design Specialist
A17: SV-14 | B17: Catalog/vault reachability defined for tunnel-down | C17: catalog_mcp.py and vault_mcp.py on hermes-vps both call out to fileserver:3003 over the WireGuard tunnel. 03_Model_Routing_Resilience's MR-05 fire drill only covers the local model falling back to Codex — it does NOT cover what happens to Hermes's memory and secrets access if the same tunnel is down. SUPERSEDED by the 2026-10-04 VPS self-sufficiency rule: the answer isn't 'define acceptable degradation,' it's 'this dependency on the home network isn't allowed to exist' — see SV-15. | D17: Either / Bridge | E17: Not Started | G17: 12 | H17: =IF(E17="Done",G17,IF(E17="Partial",G17*0.5,0)) | I17: Hermes Design Specialist | J17: Resolved in principle by SV-15; this row closes once that migration lands
A18: SV-15 | B18: Catalog + vault migrated off fileserver | C18: Required by the 2026-10-04 VPS self-sufficiency rule: hermes-vps must be able to do everything except run the local LLM without depending on the home network. Catalog + vault currently live on fileserver, which violates this. Target: Vultr Managed Database (Postgres, supports pgvector for free) — also solves IM-05's memory-provider storage need in the same move. | D18: Hermes-VPS | E18: Not Started | F18: hermes-catalog-vault-migration-required-2026-10-04 | G18: 12 | H18: =IF(E18="Done",G18,IF(E18="Partial",G18*0.5,0)) | I18: Hermes Design Specialist | J18: Closes SV-14 entirely once done; also unblocks IM-05's Hindsight shared-database option
A19: SV-13 | B19: Human-side passcode storage policy | C19: Define how the vault/Salt passcode is stored and retrieved on the human side (e.g. a password manager entry) so it never needs to be typed into a chat session. | D19: N/A (process/doc) | E19: Not Started | G19: 5 | H19: =IF(E19="Done",G19,IF(E19="Partial",G19*0.5,0)) | I19: Product Owner (Mark) | J19: Passcode was typed directly in chat on 2026-10-03; not persisted anywhere by Claude, but this feature would make that unnecessary going forward
A20: SV-16 | B20: Hermes native Credential Vault + Credential Pools -- reviewed, not adopted | C20: Found 2026-10-05: Hermes ships its own local browser-password vault (~/.hermes/vault/, Fernet-encrypted, distinct from the catalog vault above) and a Credential Pools feature (multiple API keys per provider, auto-rotation on rate-limit). Neither currently used. Pools could add resilience to Anthropic/OpenRouter calls cheaply if ever rate-limited; native Vault is the natural home for any login credentials TM-14's Obscura browser automation needs to fill. | D20: Hermes-VPS | E20: Not Started | F20: hermes-web-dashboard-survey-2026-10-05 | G20: 3 | H20: =IF(E20="Done",G20,IF(E20="Partial",G20*0.5,0)) | I20: Hermes Design Specialist | J20: No action needed yet -- noting the capability exists for when Obscura or rate-limiting makes it relevant Found 2026-10-05: hermes egress (iron-proxy) composes with Bitwarden Secrets Manager specifically for sandbox credential protection (opaque proxy tokens, Docker-backend only, matches CR-17). OPEN QUESTION, not resolved: does it require Bitwarden specifically, or can it pull from the existing catalog vault instead? Don't adopt Bitwarden as a new system without checking this first. See D8_Advanced_Reference.
H21: =IF(E21="Done",G21,IF(E21="Partial",G21*0.5,0))
H22: =IF(E22="Done",G22,IF(E22="Partial",G22*0.5,0))
H23: =IF(E23="Done",G23,IF(E23="Partial",G23*0.5,0))
H24: =IF(E24="Done",G24,IF(E24="Partial",G24*0.5,0))
H25: =IF(E25="Done",G25,IF(E25="Partial",G25*0.5,0))
H26: =IF(E26="Done",G26,IF(E26="Partial",G26*0.5,0))
H27: =IF(E27="Done",G27,IF(E27="Partial",G27*0.5,0))
H28: =IF(E28="Done",G28,IF(E28="Partial",G28*0.5,0))
H29: =IF(E29="Done",G29,IF(E29="Partial",G29*0.5,0))
H30: =IF(E30="Done",G30,IF(E30="Partial",G30*0.5,0))
H31: =IF(E31="Done",G31,IF(E31="Partial",G31*0.5,0))
H32: =IF(E32="Done",G32,IF(E32="Partial",G32*0.5,0))
... H49: =IF(E49="Done",G49,IF(E49="Partial",G49*0.5,0))
B51: TAB TOTAL (includes blank headroom rows above for future additions) | G51: =SUM(G5:G49) | H51: =SUM(H5:H49) | I51: =IFERROR(TEXT(H51/G51,"0%")&" complete","0% complete")

Sheet 06_Home_Network_Boundary
A1: Home-Network Capability Boundary
A2: The home network is a swappable capability PROVIDER, reached over WireGuard. It is never where Hermes lives.
A4: ID | B4: Feature | C4: Description (execution level) | D4: Must Live On | E4: Status | F4: Evidence / Location | G4: Points | H4: Points Earned | I4: Owner Role | J4: Notes / Next Action
A5: HN-01 | B5: WireGuard tunnel live, subnet routing confirmed | C5: 10.60.0.0/24, VPS 10.60.0.1 / home 10.60.0.2 on fileserver, verified ping + API reachability end-to-end. | D5: Home-Network | E5: Done | F5: fileserver WireGuard container | G5: 10 | H5: =IF(E5="Done",G5,IF(E5="Partial",G5*0.5,0)) | I5: Home-Network Liaison
A6: HN-02 | B6: IP forwarding + NAT + FORWARD rules | C6: net.ipv4.ip_forward=1, explicit ACCEPT persisted in PostUp/PostDown. | D6: Home-Network | E6: Done | F6: fileserver | G6: 5 | H6: =IF(E6="Done",G6,IF(E6="Partial",G6*0.5,0)) | I6: Home-Network Liaison
A7: HN-03 | B7: Home-network capability scope documented in one place | C7: Two same-day 2026-09-23 decisions define this: web/Docker presence moved to the VPS specifically to avoid exposing home ports, AND the VPN was explicitly scoped to also carry Salt (not just the local model) — both were deliberate, not sequential scope creep. Worth writing down as one coherent statement instead of two separate catalog entities a reader has to reconcile. | D7: N/A (process/doc) | E7: Not Started | F7: hermes-web-and-docker-presence-shifts-to-vps-2026-09-23, hermes-vpn-scope-includes-salt-2026-09-23 | G7: 5 | H7: =IF(E7="Done",G7,IF(E7="Partial",G7*0.5,0)) | I7: Hermes Design Specialist
A8: HN-04 | B8: Device-management capability, current state documented | C8: MeshCentral (the original device-mgmt pick) was fully replaced by Apache Guacamole 2026-10-01 — RDP/SSH native, no agent install needed, proven end-to-end for w_workstation. This row now just needs the remaining hosts (w_desktop, fileserver, server) confirmed through Guacamole too. | D8: Home-Network | E8: Partial | F8: guacamole-deployed-fileserver-2026-10-01 | G8: 5 | H8: =IF(E8="Done",G8,IF(E8="Partial",G8*0.5,0)) | I8: Home-Network Liaison
A9: HN-05 | B9: Gateway arbitrary-shell exposure closed | C9: GATEWAY_ALLOW_ALL_USERS=true + 0.0.0.0 + local terminal backend = unauthenticated shell access over the tunnel/LAN. Hermes's own docs warn against this combination. | D9: Hermes-VPS | E9: Not Started | F9: hermes-vps config.yaml | G9: 15 | H9: =IF(E9="Done",G9,IF(E9="Partial",G9*0.5,0)) | I9: Security Reviewer | J9: High priority — add an allowlist or disable ALLOW_ALL_USERS. Scored here; see 12_Security_Hardening SH-02 cross-reference
A10: HN-06 | B10: Tunnel-down alerting | C10: No notification today if the WireGuard link drops — ties to MR-05's fire drill. | D10: Either / Bridge | E10: Not Started | G10: 5 | H10: =IF(E10="Done",G10,IF(E10="Partial",G10*0.5,0)) | I10: Observability
A11: HN-07 | B11: Minimum-exposure audit of tunnel ACL | C11: Confirm only catalog/Salt/LLM ports are actually reachable over the tunnel, nothing incidental. | D11: Home-Network | E11: Not Started | G11: 5 | H11: =IF(E11="Done",G11,IF(E11="Partial",G11*0.5,0)) | I11: Security Reviewer
A12: HN-08 | B12: WireGuard key rotation policy | C12: No defined cadence or trigger for rotating the tunnel keypair. | D12: Home-Network | E12: Not Started | G12: 3 | H12: =IF(E12="Done",G12,IF(E12="Partial",G12*0.5,0)) | I12: Security Reviewer
